Workbook

Sheet 工作表1
AX5: =Z72 -> 官嶼里
D6: 陳玉珍得票率
C7: 0.3 | F7: 0.4 | I7: 0.5 | L7: 0.6 | O7: 0.7 | T7: =B42 -> 古寧村 | Y7: =B47 -> 安美村 | AS7: =Z67 -> 西園里 | AX7: =AA72 -> ①吳炎成 | BA7: =AD72 -> 1 | BC7: =Z47 -> 三山里
AX8: =AA73 -> ②李炷烽 | BA8: =AD73 -> 73
T9: =C42 -> ①吳炎成 | W9: =G42 -> 5 | Y9: =C47 -> ①吳炎成 | AB9: =G47 -> 14 | AS9: =AA67 -> ①吳炎成 | AV9: =AD67 -> 8 | AX9: =AA74 -> ③黃積軍 | BA9: =AD74 -> 2 | BC9: =AA47 -> ①吳炎成 | BF9: =AD47 -> 11
D10: 尚文凱得票率 | T10: =C43 -> ②李炷烽 | W10: =G43 -> 485 | Y10: =C48 -> ②李炷烽 | AB10: =G48 -> 321 | AN10: =Z77 -> 浦山里 | AS10: =AA68 -> ②李炷烽 | AV10: =AD68 -> 136 | AX10: =Z42 -> 汶沙里 | BC10: =AA48 -> ②李炷烽 | BF10: =AD48 -> 216
C11: 0.3 | F11: 0.4 | I11: 0.5 | L11: 0.6 | O11: 0.7 | T11: =C44 -> ③黃積軍 | W11: =G44 -> 5 | Y11: =C49 -> ③黃積軍 | AB11: =G49 -> 8 | AS11: =AA69 -> ③黃積軍 | AV11: =AD69 -> 9 | BC11: =AA49 -> ③黃積軍 | BF11: =AD49 -> 6
Y12: =B57 -> 湖埔村 | AD12: =B52 -> 后盤村 | AN12: =AA77 -> ①吳炎成 | AQ12: =AD77 -> 9 | AS12: =Z62 -> 何斗里 | AX12: =AA42 -> ①吳炎成 | BA12: =AD42 -> 30 | BC12: =Z52 -> 大洋里
AN13: =AA78 -> ②李炷烽 | AQ13: =AD78 -> 243 | AX13: =AA43 -> ②李炷烽 | BA13: =AD43 -> 558
Y14: =C57 -> ①吳炎成 | AB14: =F57 -> 0 | AD14: =C52 -> ①吳炎成 | AG14: =F52 -> 0 | AN14: =AA79 -> ③黃積軍 | AQ14: =AD79 -> 5 | AS14: =AA62 -> ①吳炎成 | AV14: =AD62 -> 14 | AX14: =AA44 -> ③黃積軍 | BA14: =AD44 -> 17 | BC14: =AA52 -> ①吳炎成 | BF14: =AD52 -> 12
H15: =AX52 -> 西口村 | Y15: =C58 -> ②李炷烽 | AB15: =F58 -> 0 | AD15: =C53 -> ②李炷烽 | AG15: =F53 -> 0 | AI15: =B67 -> 盤山村 | AN15: =AL62 -> 瓊林里 | AS15: =AA63 -> ②李炷烽 | AV15: =AD63 -> 166 | AX15: =Z57 -> 光前里 | BC15: =AA53 -> ②李炷烽 | BF15: =AD53 -> 120
Y16: =C59 -> ③黃積軍 | AB16: =F59 -> 0 | AD16: =C54 -> ③黃積軍 | AG16: =F54 -> 0 | AS16: =AA64 -> ③黃積軍 | AV16: =AD64 -> 6 | BC16: =AA54 -> ③黃積軍 | BF16: =AD54 -> 2
C17: =AX47 -> 上林村 | H17: =AY52 -> ①吳炎成 | K17: =BB52 -> 3 | M17: =AX62 -> 黃埔村 | Y17: =N47 -> 西門里 | AD17: =N57 -> 北門里 | AI17: =C67 -> ①吳炎成 | AL17: =F67 -> 0 | AN17: =AM62 -> ①吳炎成 | AQ17: =AP62 -> 19 | AS17: =AL47 -> 山外里 | AX17: =AA57 -> ①吳炎成 | BA17: =AD57 -> 8 | BC17: =AL72 -> 溪湖里
H18: =AY53 -> ②李炷烽 | K18: =BB53 -> 127 | AI18: =C68 -> ②李炷烽 | AL18: =F68 -> 0 | AN18: =AM63 -> ②李炷烽 | AQ18: =AP63 -> 321 | AX18: =AA58 -> ②李炷烽 | BA18: =AD58 -> 199
C19: =AY47 -> ①吳炎成 | F19: =BB47 -> 1 | H19: =AY54 -> ③黃積軍 | K19: =BB54 -> 2 | M19: =AY62 -> ①吳炎成 | P19: =BB62 -> 6 | Y19: =O47 -> ①吳炎成 | AB19: =R47 -> 24 | AD19: =O57 -> ①吳炎成 | AG19: =R57 -> 12 | AI19: =C69 -> ③黃積軍 | AL19: =F69 -> 0 | AN19: =AM64 -> ③黃積軍 | AQ19: =AP64 -> 8 | AS19: =AM47 -> ①吳炎成 | AV19: =AP47 -> 24 | AX19: =AA59 -> ③黃積軍 | BA19: =AD59 -> 13 | BC19: =AM72 -> ①吳炎成 | BF19: =AP72 -> 15
C20: =AY48 -> ②李炷烽 | F20: =BB48 -> 141 | H20: =AX57 -> 林湖村 | M20: =AY63 -> ②李炷烽 | P20: =BB63 -> 113 | Y20: =O48 -> ②李炷烽 | AB20: =R48 -> 895 | AD20: =O58 -> ②李炷烽 | AG20: =R58 -> 463 | AI20: =B62 -> 榜林村 | AN20: =AL52 -> 正義里 | AS20: =AM48 -> ②李炷烽 | AV20: =AP48 -> 381 | AX20: =AL42 -> 新市里 | BC20: =AM73 -> ②李炷烽 | BF20: =AP73 -> 157
C21: =AY49 -> ③黃積軍 | F21: =BB49 -> 2 | M21: =AY64 -> ③黃積軍 | P21: =BB64 -> 6 | Y21: =O49 -> ③黃積軍 | AB21: =R49 -> 19 | AD21: =O59 -> ③黃積軍 | AG21: =R59 -> 15 | AS21: =AM49 -> ③黃積軍 | AV21: =AP49 -> 7 | BC21: =AM74 -> ③黃積軍 | BF21: =AP74 -> 5
C22: =AX42 -> 上岐村 | H22: =AY57 -> ①吳炎成 | K22: =BB57 -> 8 | Y22: =N52 -> 南門里 | AD22: =N42 -> 東門里 | AI22: =C62 -> ①吳炎成 | AL22: =F62 -> 0 | AN22: =AM52 -> ①吳炎成 | AQ22: =AP52 -> 15 | AS22: =AL67 -> 新湖里 | AX22: =AM42 -> ①吳炎成 | BA22: =AP42 -> 22 | BC22: =AL77 -> 蓮庵里
H23: =AY58 -> ②李炷烽 | K23: =BB58 -> 344 | AI23: =C63 -> ②李炷烽 | AL23: =F63 -> 0 | AN23: =AM53 -> ②李炷烽 | AQ23: =AP53 -> 237 | AX23: =AM43 -> ②李炷烽 | BA23: =AP43 -> 595
C24: =AY42 -> ①吳炎成 | F24: =BB42 -> 9 | H24: =AY59 -> ③黃積軍 | K24: =BB59 -> 5 | Y24: =O52 -> ①吳炎成 | AB24: =R52 -> 24 | AD24: =O42 -> ①吳炎成 | AG24: =R42 -> 16 | AI24: =C64 -> ③黃積軍 | AL24: =F64 -> 0 | AN24: =AM54 -> ③黃積軍 | AQ24: =AP54 -> 14 | AS24: =AM67 -> ①吳炎成 | AV24: =AP67 -> 25 | AX24: =AM44 -> ③黃積軍 | BA24: =AP44 -> 14 | BC24: =AM77 -> ①吳炎成 | BF24: =AP77 -> 2
C25: =AY43 -> ②李炷烽 | F25: =BB43 -> 291 | Y25: =O53 -> ②李炷烽 | AB25: =R53 -> 695 | AD25: =O43 -> ②李炷烽 | AG25: =R43 -> 423 | AS25: =AM68 -> ②李炷烽 | AV25: =AP68 -> 348 | AX25: =AL57 -> 料羅里 | BC25: =AM78 -> ②李炷烽 | BF25: =AP78 -> 121
C26: =AY44 -> ③黃積軍 | F26: =BB44 -> 6 | Y26: =O54 -> ③黃積軍 | AB26: =R54 -> 24 | AD26: =O44 -> ③黃積軍 | AG26: =R44 -> 12 | AS26: =AM69 -> ③黃積軍 | AV26: =AP69 -> 16 | BC26: =AM79 -> ③黃積軍 | BF26: =AP79 -> 8
R27: =N67 -> 金水里 | W27: =N77 -> 賢庵里 | AB27: =N72 -> 珠沙里 | AX27: =AM57 -> ①吳炎成 | BA27: =AP57 -> 10
AX28: =AM58 -> ②李炷烽 | BA28: =AP58 -> 193
C29: 烈嶼鄉 | D29: =AY42 -> ①吳炎成 | H29: =SUMIF(AY42:BB64,D29,BC42:BE64) -> 27 | K29: =H29/SUM(H29:H31) -> 0.02537594 | R29: =O67 -> ①吳炎成 | U29: =R67 -> 3 | W29: =O77 -> ①吳炎成 | Z29: =R77 -> 20 | AB29: =O72 -> ①吳炎成 | AE29: =R72 -> 3 | AI29: 金沙鎮 | AJ29: =AA42 -> ①吳炎成 | AM29: =SUM(AD42,AD47,AD52,AD57,AD62,AD67,AD72,AD77) -> 93 | AN29: =SUMIF(AA42:AD79,AJ29,AE42:AG79) -> 93 | AP29: =AM29/7105 -> 0.013089374 | AQ29: =AN29/SUM(AN29:AN31) -> 0.049892704 | AX29: =AM59 -> ③黃積軍 | BA29: =AP59 -> 6
D30: =AY43 -> ②李炷烽 | H30: =SUMIF(AY42:BB64,D30,BC42:BE64) -> 1016 | J30: =G30/4168 -> 0 | K30: =H30/SUM(H29:H31) -> 0.95488722 | R30: =O68 -> ②李炷烽 | U30: =R68 -> 166 | W30: =O78 -> ②李炷烽 | Z30: =R78 -> 337 | AB30: =O73 -> ②李炷烽 | AE30: =R73 -> 156 | AJ30: =AA43 -> ②李炷烽 | AM30: =SUM(AD43,AD48,AD53,AD58,AD63,AD68,AD73,AD78) -> 1711 | AN30: =SUMIF(AA42:AD79,AJ30,AE42:AG79) -> 1711 | AP30: =AM30/7105 -> 0.24081633 | AQ30: =AN30/SUM(AN29:AN31) -> 0.91791845
D31: =AY44 -> ③黃積軍 | H31: =SUMIF(AY42:BB64,D31,BC42:BE64) -> 21 | J31: =G31/4168 -> 0 | K31: =H31/SUM(H29:H31) -> 0.019736842 | R31: =O69 -> ③黃積軍 | U31: =R69 -> 33 | W31: =O79 -> ③黃積軍 | Z31: =R79 -> 12 | AB31: =O74 -> ③黃積軍 | AE31: =R74 -> 2 | AJ31: =AA44 -> ③黃積軍 | AM31: =SUM(AD44,AD49,AD54,AD59,AD64,AD69,AD74,AD79) -> 60 | AN31: =SUMIF(AA42:AD79,AJ31,AE42:AG79) -> 60 | AP31: =AM31/7105 -> 0.0084447572 | AQ31: =AN31/SUM(AN29:AN31) -> 0.032188841
C32: 金寧鄉 | D32: =C42 -> ①吳炎成 | G32: =SUM(F42,F47,F52,F57,F62,F67) -> 0 | H32: =SUMIF(C42:F69,D32,G42:I69) -> 54 | J32: =G32/10846 -> 0 | K32: =H32/SUM(H32:H34) -> 0.028465999 | W32: =N62 -> 古城里 | AI32: 金湖鎮 | AJ32: =AM42 -> ①吳炎成 | AM32: =SUM(AP42,AP47,AP52,AP57,AP62,AP67,AP72,AP77) -> 132 | AN32: =SUMIF(AM42:AP79,AJ32,AQ42:AS79) -> 132 | AP32: =AM32/10668 -> 0.012373453 | AQ32: =AN32/SUM(AN32:AN34) -> 0.051502146 | AW32: =AX69 -> 大坵村
D33: =C43 -> ②李炷烽 | G33: =SUM(F43,F48,F53,F58,F63,F68) -> 0 | H33: =SUMIF(C42:F69,D33,G42:I69) -> 1822 | J33: =G33/10846 -> 0 | K33: =H33/SUM(H32:H34) -> 0.96046389 | AJ33: =AM43 -> ②李炷烽 | AM33: =SUM(AP43,AP48,AP53,AP58,AP63,AP68,AP73,AP78) -> 2353 | AN33: =SUMIF(AM42:AP79,AJ33,AQ42:AS79) -> 2353 | AP33: =AM33/10668 -> 0.22056618 | AQ33: =AN33/SUM(AN32:AN34) -> 0.91806477
D34: =C44 -> ③黃積軍 | G34: =SUM(F44,F49,F54,F59,F64,F69) -> 0 | H34: =SUMIF(C42:F69,D34,G42:I69) -> 21 | J34: =G34/10846 -> 0 | K34: =H34/SUM(H32:H34) -> 0.011070111 | W34: =O62 -> ①吳炎成 | Z34: =R57 -> 12 | AJ34: =AM44 -> ③黃積軍 | AM34: =SUM(AP44,AP49,AP54,AP59,AP64,AP69,AP74,AP79) -> 78 | AN34: =SUMIF(AM42:AP79,AJ34,AQ42:AS79) -> 78 | AP34: =AM34/10668 -> 0.0073115861 | AQ34: =AN34/SUM(AN32:AN34) -> 0.030433086 | AW34: =AY69 -> ①吳炎成 | AZ34: =BB69 -> 0
C35: 金城鎮 | D35: =O42 -> ①吳炎成 | G35: =SUM(R42,R47,R52,R57,R62,R67,R72,R77) -> 112 | H35: =SUMIF(O42:O79,D35,S42:S79) -> 112 | J35: =G35/14119 -> 0.0079325731 | K35: =H35/SUM(H35:H37) -> 0.030930682 | W35: =O63 -> ②李炷烽 | Z35: =R58 -> 463 | AI35: 烏坵鄉 | AJ35: =AY69 -> ①吳炎成 | AM35: =SUM(BB69,BB72) -> 3 | AN35: =SUMIF(AY69:BB74,AJ35,BC69:BE74) -> 0 | AP35: =AM35/208 -> 0.014423077 | AQ35: =AN35/SUM(AN35:AN37) -> 0 | AW35: =AY70 -> ②李炷烽 | AZ35: =BB70 -> 1
D36: =O43 -> ②李炷烽 | G36: =SUM(R43,R48,R53,R58,R63,R68,R73,R78) -> 3386 | H36: =SUMIF(O42:O79,D36,S42:S79) -> 3386 | J36: =G36/14119 -> 0.23981868 | K36: =H36/SUM(H35:H37) -> 0.9351008 | W36: =O64 -> ③黃積軍 | Z36: =R59 -> 15 | AJ36: =AY70 -> ②李炷烽 | AM36: =SUM(BB70,BB73) -> 10 | AN36: =SUMIF(AY69:BB74,AJ36,BC69:BE74) -> 1 | AP36: =AM36/208 -> 0.048076923 | AQ36: =AN36/SUM(AN35:AN37) -> 1 | AW36: =AY71 -> ③黃積軍 | AZ36: =BB71 -> 0
D37: =O44 -> ③黃積軍 | G37: =SUM(R44,R49,R54,R59,R64,R69,R74,R79) -> 123 | H37: =SUMIF(O42:O79,D37,S42:S79) -> 123 | J37: =G37/14119 -> 0.0087116651 | K37: =H37/SUM(H35:H37) -> 0.033968517 | AJ37: =AY71 -> ③黃積軍 | AM37: =SUM(BB71,BB74) -> 0 | AN37: =SUMIF(AY69:BB74,AJ37,BC69:BE74) -> 0 | AP37: =AM37/208 -> 0 | AQ37: =AN37/SUM(AN35:AN37) -> 0
B39: 1996年金門縣國大代表選舉︱投票日：1996.3.23，選舉人數 30173，投票數 20938，有效票 20275，無效票 663，投票率 69.39% | BH39: 資料來源｜政大選舉研究中心，製表｜OS259
B41: 金寧鄉 | N41: 金城鎮 | Z41: 金沙鎮 | AL41: 金湖鎮 | AX41: 烈嶼鄉
B42: 古寧村 | C42: =金寧鄉!B2 -> ①吳炎成 | G42: =金寧鄉!D2 -> 5 | J42: =G42/SUM(G$42:G$46) -> 0.0080906149 | M42: =IF(MAX(J$42:J$44)=J42,IF(J42>=0.7,1,IF(J42>=0.6,2,IF(J42>=0.5,3,IF(J42>=0.4,4,5)))),0) -> 0 | N42: 東門里 | O42: =金城鎮!B2 -> ①吳炎成 | R42: =金城鎮!D2 -> 16 | S42: =金城鎮!D2 -> 16 | V42: =S42/SUM(S$42:S$46) -> 0.016736402 | Y42: =IF(MAX(V$42:V$44)=V42,IF(V42>=0.7,1,IF(V42>=0.6,2,IF(V42>=0.5,3,IF(V42>=0.4,4,5)))),0) -> 0 | Z42: 汶沙里 | AA42: =金沙鎮!B2 -> ①吳炎成 | AD42: =金沙鎮!D2 -> 30 | AE42: =金沙鎮!D2 -> 30 | AH42: =AE42/SUM(AE$42:AE$46) -> 0.029211295 | AK42: =IF(MAX(AH$42:AH$44)=AH42,IF(AH42>=0.7,1,IF(AH42>=0.6,2,IF(AH42>=0.5,3,IF(AH42>=0.4,4,5)))),0) -> 0 | AL42: 新市里 | AM42: =金湖鎮!B2 -> ①吳炎成 | AP42: =金湖鎮!D2 -> 22 | AQ42: =金湖鎮!D2 -> 22 | AT42: =AQ42/SUM(AQ$42:AQ$46) -> 0.021093001 | AW42: =IF(MAX(AT$42:AT$44)=AT42,IF(AT42>=0.7,1,IF(AT42>=0.6,2,IF(AT42>=0.5,3,IF(AT42>=0.4,4,5)))),0) -> 0 | AX42: 上岐村 | AY42: =烈嶼鄉!B2 -> ①吳炎成 | BB42: =烈嶼鄉!D2 -> 9 | BC42: =烈嶼鄉!D2 -> 9 | BF42: =BC42/SUM(BC$42:BC$46) -> 0.018442623 | BI42: =IF(MAX(BF$42:BF$44)=BF42,IF(BF42>=0.7,1,IF(BF42>=0.6,2,IF(BF42>=0.5,3,IF(BF42>=0.4,4,5)))),0) -> 0
C43: =金寧鄉!B3 -> ②李炷烽 | G43: =金寧鄉!D3 -> 485 | J43: =G43/SUM(G$42:G$46) -> 0.78478964 | M43: =IF(MAX(J$42:J$44)=J43,IF(J43>=0.7,1,IF(J43>=0.6,2,IF(J43>=0.5,3,IF(J43>=0.4,4,5)))),0) -> 1 | O43: =金城鎮!B3 -> ②李炷烽 | R43: =金城鎮!D3 -> 423 | S43: =金城鎮!D3 -> 423 | V43: =S43/SUM(S$42:S$46) -> 0.44246862 | Y43: =IF(MAX(V$42:V$44)=V43,IF(V43>=0.7,1,IF(V43>=0.6,2,IF(V43>=0.5,3,IF(V43>=0.4,4,5)))),0) -> 4 | AA43: =金沙鎮!B3 -> ②李炷烽 | AD43: =金沙鎮!D3 -> 558 | AE43: =金沙鎮!D3 -> 558 | AH43: =AE43/SUM(AE$42:AE$46) -> 0.54333009 | AK43: =IF(MAX(AH$42:AH$44)=AH43,IF(AH43>=0.7,1,IF(AH43>=0.6,2,IF(AH43>=0.5,3,IF(AH43>=0.4,4,5)))),0) -> 3 | AM43: =金湖鎮!B3 -> ②李炷烽 | AP43: =金湖鎮!D3 -> 595 | AQ43: =金湖鎮!D3 -> 595 | AT43: =AQ43/SUM(AQ$42:AQ$46) -> 0.5704698 | AW43: =IF(MAX(AT$42:AT$44)=AT43,IF(AT43>=0.7,1,IF(AT43>=0.6,2,IF(AT43>=0.5,3,IF(AT43>=0.4,4,5)))),0) -> 3 | AY43: =烈嶼鄉!B3 -> ②李炷烽 | BB43: =烈嶼鄉!D3 -> 291 | BC43: =烈嶼鄉!D3 -> 291 | BF43: =BC43/SUM(BC$42:BC$46) -> 0.59631148 | BI43: =IF(MAX(BF$42:BF$44)=BF43,IF(BF43>=0.7,1,IF(BF43>=0.6,2,IF(BF43>=0.5,3,IF(BF43>=0.4,4,5)))),0) -> 3
C44: =金寧鄉!B4 -> ③黃積軍 | G44: =金寧鄉!D4 -> 5 | J44: =G44/SUM(G$42:G$46) -> 0.0080906149 | M44: =IF(MAX(J$42:J$44)=J44,IF(J44>=0.7,1,IF(J44>=0.6,2,IF(J44>=0.5,3,IF(J44>=0.4,4,5)))),0) -> 0 | O44: =金城鎮!B4 -> ③黃積軍 | R44: =金城鎮!D4 -> 12 | S44: =金城鎮!D4 -> 12 | V44: =S44/SUM(S$42:S$46) -> 0.012552301 | Y44: =IF(MAX(V$42:V$44)=V44,IF(V44>=0.7,1,IF(V44>=0.6,2,IF(V44>=0.5,3,IF(V44>=0.4,4,5)))),0) -> 0 | AA44: =金沙鎮!B4 -> ③黃積軍 | AD44: =金沙鎮!D4 -> 17 | AE44: =金沙鎮!D4 -> 17 | AH44: =AE44/SUM(AE$42:AE$46) -> 0.016553067 | AK44: =IF(MAX(AH$42:AH$44)=AH44,IF(AH44>=0.7,1,IF(AH44>=0.6,2,IF(AH44>=0.5,3,IF(AH44>=0.4,4,5)))),0) -> 0 | AM44: =金湖鎮!B4 -> ③黃積軍 | AP44: =金湖鎮!D4 -> 14 | AQ44: =金湖鎮!D4 -> 14 | AT44: =AQ44/SUM(AQ$42:AQ$46) -> 0.013422819 | AW44: =IF(MAX(AT$42:AT$44)=AT44,IF(AT44>=0.7,1,IF(AT44>=0.6,2,IF(AT44>=0.5,3,IF(AT44>=0.4,4,5)))),0) -> 0 | AY44: =烈嶼鄉!B4 -> ③黃積軍 | BB44: =烈嶼鄉!D4 -> 6 | BC44: =烈嶼鄉!D4 -> 6 | BF44: =BC44/SUM(BC$42:BC$46) -> 0.012295082 | BI44: =IF(MAX(BF$42:BF$44)=BF44,IF(BF44>=0.7,1,IF(BF44>=0.6,2,IF(BF44>=0.5,3,IF(BF44>=0.4,4,5)))),0) -> 0
C45: =金寧鄉!B5 -> ④楊肅元 | G45: =金寧鄉!D5 -> 63 | J45: =G45/SUM(G$42:G$46) -> 0.10194175 | M45: =IF(MAX(J$42:J$44)=J45,IF(J45>=0.7,1,IF(J45>=0.6,2,IF(J45>=0.5,3,IF(J45>=0.4,4,5)))),0) -> 0 | O45: =金城鎮!B5 -> ④楊肅元 | R45: =金城鎮!D5 -> 390 | S45: =金城鎮!D5 -> 390 | V45: =S45/SUM(S$42:S$46) -> 0.40794979 | Y45: =IF(MAX(V$42:V$44)=V45,IF(V45>=0.7,1,IF(V45>=0.6,2,IF(V45>=0.5,3,IF(V45>=0.4,4,5)))),0) -> 0 | AA45: =金沙鎮!B5 -> ④楊肅元 | AD45: =金沙鎮!D5 -> 271 | AE45: =金沙鎮!D5 -> 271 | AH45: =AE45/SUM(AE$42:AE$46) -> 0.26387537 | AK45: =IF(MAX(AH$42:AH$44)=AH45,IF(AH45>=0.7,1,IF(AH45>=0.6,2,IF(AH45>=0.5,3,IF(AH45>=0.4,4,5)))),0) -> 0 | AM45: =金湖鎮!B5 -> ④楊肅元 | AP45: =金湖鎮!D5 -> 244 | AQ45: =金湖鎮!D5 -> 244 | AT45: =AQ45/SUM(AQ$42:AQ$46) -> 0.23394056 | AW45: =IF(MAX(AT$42:AT$44)=AT45,IF(AT45>=0.7,1,IF(AT45>=0.6,2,IF(AT45>=0.5,3,IF(AT45>=0.4,4,5)))),0) -> 0 | AY45: =烈嶼鄉!B5 -> ④楊肅元 | BB45: =烈嶼鄉!D5 -> 91 | BC45: =烈嶼鄉!D5 -> 91 | BF45: =BC45/SUM(BC$42:BC$46) -> 0.18647541 | BI45: =IF(MAX(BF$42:BF$44)=BF45,IF(BF45>=0.7,1,IF(BF45>=0.6,2,IF(BF45>=0.5,3,IF(BF45>=0.4,4,5)))),0) -> 0
C46: =金寧鄉!B6 -> ⑤翟美玉 | G46: =金寧鄉!D6 -> 60 | J46: =G46/SUM(G$42:G$46) -> 0.097087379 | M46: =IF(MAX(J$42:J$44)=J46,IF(J46>=0.7,1,IF(J46>=0.6,2,IF(J46>=0.5,3,IF(J46>=0.4,4,5)))),0) -> 0 | O46: =金城鎮!B6 -> ⑤翟美玉 | R46: =金城鎮!D6 -> 115 | S46: =金城鎮!D6 -> 115 | V46: =S46/SUM(S$42:S$46) -> 0.12029289 | Y46: =IF(MAX(V$42:V$44)=V46,IF(V46>=0.7,1,IF(V46>=0.6,2,IF(V46>=0.5,3,IF(V46>=0.4,4,5)))),0) -> 0 | AA46: =金沙鎮!B6 -> ⑤翟美玉 | AD46: =金沙鎮!D6 -> 151 | AE46: =金沙鎮!D6 -> 151 | AH46: =AE46/SUM(AE$42:AE$46) -> 0.14703019 | AK46: =IF(MAX(AH$42:AH$44)=AH46,IF(AH46>=0.7,1,IF(AH46>=0.6,2,IF(AH46>=0.5,3,IF(AH46>=0.4,4,5)))),0) -> 0 | AM46: =金湖鎮!B6 -> ⑤翟美玉 | AP46: =金湖鎮!D6 -> 168 | AQ46: =金湖鎮!D6 -> 168 | AT46: =AQ46/SUM(AQ$42:AQ$46) -> 0.16107383 | AW46: =IF(MAX(AT$42:AT$44)=AT46,IF(AT46>=0.7,1,IF(AT46>=0.6,2,IF(AT46>=0.5,3,IF(AT46>=0.4,4,5)))),0) -> 0 | AY46: =烈嶼鄉!B6 -> ⑤翟美玉 | BB46: =烈嶼鄉!D6 -> 91 | BC46: =烈嶼鄉!D6 -> 91 | BF46: =BC46/SUM(BC$42:BC$46) -> 0.18647541 | BI46: =IF(MAX(BF$42:BF$44)=BF46,IF(BF46>=0.7,1,IF(BF46>=0.6,2,IF(BF46>=0.5,3,IF(BF46>=0.4,4,5)))),0) -> 0
...

Sheet 圖表數據
C2: 吳炎成 | D2: 李炷烽 | E2: 黃積軍 | F2: 楊肅元 | G2: 翟美玉
B3: 金城鎮 | C3: =SUM(金城鎮!D2,金城鎮!D7,金城鎮!D12,金城鎮!D17,金城鎮!D22,金城鎮!D27,金城鎮!D32,金城鎮!D37) -> 112 | D3: =SUM(金城鎮!D3,金城鎮!D8,金城鎮!D13,金城鎮!D18,金城鎮!D23,金城鎮!D28,金城鎮!D33,金城鎮!D38) -> 3386 | E3: =SUM(金城鎮!D4,金城鎮!D9,金城鎮!D14,金城鎮!D19,金城鎮!D24,金城鎮!D29,金城鎮!D34,金城鎮!D39) -> 123 | F3: =SUM(金城鎮!D5,金城鎮!D10,金城鎮!D15,金城鎮!D20,金城鎮!D25,金城鎮!D30,金城鎮!D35,金城鎮!D40) -> 1710 | G3: =SUM(金城鎮!D6,金城鎮!D11,金城鎮!D16,金城鎮!D21,金城鎮!D26,金城鎮!D31,金城鎮!D36,金城鎮!D41) -> 1348
B4: 金寧鄉 | C4: =SUM(金寧鄉!D2,金寧鄉!D7,金寧鄉!D12,金寧鄉!D17,金寧鄉!D22,金寧鄉!D27) -> 54 | D4: =SUM(金寧鄉!D3,金寧鄉!D8,金寧鄉!D13,金寧鄉!D18,金寧鄉!D23,金寧鄉!D28) -> 1822 | E4: =SUM(金寧鄉!D4,金寧鄉!D9,金寧鄉!D14,金寧鄉!D19,金寧鄉!D24,金寧鄉!D29) -> 21 | F4: =SUM(金寧鄉!D5,金寧鄉!D10,金寧鄉!D15,金寧鄉!D20,金寧鄉!D25,金寧鄉!D30) -> 966 | G4: =SUM(金寧鄉!D6,金寧鄉!D11,金寧鄉!D16,金寧鄉!D21,金寧鄉!D26,金寧鄉!D31) -> 679
B5: 金沙鎮 | C5: =SUM(金沙鎮!D2,金沙鎮!D7,金沙鎮!D12,金沙鎮!D17,金沙鎮!D22,金沙鎮!D27,金沙鎮!D32,金沙鎮!D37) -> 93 | D5: =SUM(金沙鎮!D3,金沙鎮!D8,金沙鎮!D13,金沙鎮!D18,金沙鎮!D23,金沙鎮!D28,金沙鎮!D33,金沙鎮!D38) -> 1711 | E5: =SUM(金沙鎮!D4,金沙鎮!D9,金沙鎮!D14,金沙鎮!D19,金沙鎮!D24,金沙鎮!D29,金沙鎮!D34,金沙鎮!D39) -> 60 | F5: =SUM(金沙鎮!D5,金沙鎮!D10,金沙鎮!D15,金沙鎮!D20,金沙鎮!D25,金沙鎮!D30,金沙鎮!D35,金沙鎮!D40) -> 788 | G5: =SUM(金沙鎮!D6,金沙鎮!D11,金沙鎮!D16,金沙鎮!D21,金沙鎮!D26,金沙鎮!D31,金沙鎮!D36,金沙鎮!D41) -> 842
B6: 金湖鎮 | C6: =SUM(金湖鎮!D2,金湖鎮!D7,金湖鎮!D12,金湖鎮!D17,金湖鎮!D22,金湖鎮!D27,金湖鎮!D32,金湖鎮!D37) -> 132 | D6: =SUM(金湖鎮!D3,金湖鎮!D8,金湖鎮!D13,金湖鎮!D18,金湖鎮!D23,金湖鎮!D28,金湖鎮!D33,金湖鎮!D38) -> 2353 | E6: =SUM(金湖鎮!D4,金湖鎮!D9,金湖鎮!D14,金湖鎮!D19,金湖鎮!D24,金湖鎮!D29,金湖鎮!D34,金湖鎮!D39) -> 78 | F6: =SUM(金湖鎮!D5,金湖鎮!D10,金湖鎮!D15,金湖鎮!D20,金湖鎮!D25,金湖鎮!D30,金湖鎮!D35,金湖鎮!D40) -> 925 | G6: =SUM(金湖鎮!D6,金湖鎮!D11,金湖鎮!D16,金湖鎮!D21,金湖鎮!D26,金湖鎮!D31,金湖鎮!D36,金湖鎮!D41) -> 1121
B7: 烈嶼鄉 | C7: =SUM(烈嶼鄉!D2,烈嶼鄉!D7,烈嶼鄉!D12,烈嶼鄉!D17,烈嶼鄉!D22) -> 27 | D7: =SUM(烈嶼鄉!D3,烈嶼鄉!D8,烈嶼鄉!D13,烈嶼鄉!D18,烈嶼鄉!D23) -> 1016 | E7: =SUM(烈嶼鄉!D4,烈嶼鄉!D9,烈嶼鄉!D14,烈嶼鄉!D19,烈嶼鄉!D24) -> 21 | F7: =SUM(烈嶼鄉!D5,烈嶼鄉!D10,烈嶼鄉!D15,烈嶼鄉!D20,烈嶼鄉!D25) -> 277 | G7: =SUM(烈嶼鄉!D6,烈嶼鄉!D11,烈嶼鄉!D16,烈嶼鄉!D21,烈嶼鄉!D26) -> 597
B8: 烏坵鄉 | C8: =SUM(烏坵鄉!D2) -> 0 | D8: =SUM(烏坵鄉!D3) -> 1 | E8: =SUM(烏坵鄉!D4) -> 0 | F8: =SUM(烏坵鄉!D5) -> 3 | G8: =SUM(烏坵鄉!D6) -> 9
B9: 總計 | C9: =SUM(C3:C8) -> 418 | D9: =SUM(D3:D8) -> 10289 | E9: =SUM(E3:E8) -> 303 | F9: =SUM(F3:F8) -> 4669 | G9: =SUM(G3:G8) -> 4596
B10: 得票率 | C10: =SUM(C3:C8)/SUM(C3:G8) -> 0.020616523 | D10: =SUM(D3:D8)/SUM(C3:G8) -> 0.50747226 | E10: =SUM(E3:E8)/SUM(C3:G8) -> 0.014944513 | F10: =SUM(F3:F8)/SUM(C3:G8) -> 0.2302836 | G10: =SUM(G3:G8)/SUM(C3:G8) -> 0.22668311

Sheet 比例色代碼
C3: 基準點：北門里
AX5: =工作表1!AX5 -> 官嶼里
T7: =工作表1!T7 -> 古寧村 | Y7: =工作表1!Y7 -> 安美村 | AS7: =工作表1!AS7 -> 西園里 | BB7: =工作表1!AK72 -> 0 | BC7: =工作表1!BC7 -> 三山里
BB8: =工作表1!AK73 -> 5
X9: =工作表1!M42 -> 0 | AC9: =工作表1!M47 -> 0 | AW9: =工作表1!AK67 -> 0 | BB9: =工作表1!AK74 -> 0 | BG9: =工作表1!AK47 -> 0
X10: =工作表1!M43 -> 1 | AC10: =工作表1!M48 -> 4 | AN10: =工作表1!AN10 -> 浦山里 | AW10: =工作表1!AK68 -> 4 | AX10: =工作表1!AX10 -> 汶沙里 | BG10: =工作表1!AK48 -> 2
X11: =工作表1!M44 -> 0 | AC11: =工作表1!M49 -> 0 | AW11: =工作表1!AK69 -> 0 | BG11: =工作表1!AK49 -> 0
Y12: =工作表1!Y12 -> 湖埔村 | AD12: =工作表1!AD12 -> 后盤村 | AR12: =工作表1!AK77 -> 0 | AS12: =工作表1!AS12 -> 何斗里 | BB12: =工作表1!AK42 -> 0 | BC12: =工作表1!BC12 -> 大洋里
AR13: =工作表1!AK78 -> 3 | BB13: =工作表1!AK43 -> 3
AC14: =工作表1!M57 -> 0 | AH14: =工作表1!M52 -> 0 | AR14: =工作表1!AK79 -> 0 | AW14: =工作表1!AK62 -> 0 | BB14: =工作表1!AK44 -> 0 | BG14: =工作表1!AK52 -> 0
H15: =工作表1!H15 -> 西口村 | AC15: =工作表1!M58 -> 5 | AH15: =工作表1!M53 -> 2 | AI15: =工作表1!AI15 -> 盤山村 | AN15: =工作表1!AN15 -> 瓊林里 | AW15: =工作表1!AK63 -> 5 | AX15: =工作表1!AX15 -> 光前里 | BG15: =工作表1!AK53 -> 3
AC16: =工作表1!M59 -> 0 | AH16: =工作表1!M54 -> 0 | AW16: =工作表1!AK64 -> 0 | BG16: =工作表1!AK54 -> 0
C17: =工作表1!C17 -> 上林村 | L17: =工作表1!BI52 -> 0 | M17: =工作表1!M17 -> 黃埔村 | Y17: =工作表1!Y17 -> 西門里 | AD17: =工作表1!AD17 -> 北門里 | AM17: =工作表1!M67 -> 0 | AR17: =工作表1!AW62 -> 0 | AS17: =工作表1!AS17 -> 山外里 | BB17: =工作表1!AK57 -> 0 | BC17: =工作表1!BC17 -> 溪湖里
L18: =工作表1!BI53 -> 5 | AM18: =工作表1!M68 -> 3 | AR18: =工作表1!AW63 -> 4 | BB18: =工作表1!AK58 -> 3
G19: =工作表1!BI47 -> 0 | L19: =工作表1!BI54 -> 0 | Q19: =工作表1!BI62 -> 0 | AC19: =工作表1!Y47 -> 0 | AH19: =工作表1!Y57 -> 0 | AM19: =工作表1!M69 -> 0 | AR19: =工作表1!AW64 -> 0 | AW19: =工作表1!AW47 -> 0 | BB19: =工作表1!AK59 -> 0 | BG19: =工作表1!AW70 -> 0
G20: =工作表1!BI48 -> 2 | H20: =工作表1!H20 -> 林湖村 | Q20: =工作表1!BI63 -> 4 | AC20: =工作表1!Y48 -> 3 | AH20: =工作表1!Y58 -> 3 | AI20: =工作表1!AI20 -> 榜林村 | AN20: =工作表1!AN20 -> 正義里 | AW20: =工作表1!AW48 -> 3 | AX20: =工作表1!AX20 -> 新市里 | BG20: =工作表1!AW71 -> 4
G21: =工作表1!BI49 -> 0 | Q21: =工作表1!BI64 -> 0 | AC21: =工作表1!Y49 -> 0 | AH21: =工作表1!Y59 -> 0 | AW21: =工作表1!AW49 -> 0 | BG21: =工作表1!AW72 -> 0
C22: =工作表1!C22 -> 上岐村 | L22: =工作表1!BI57 -> 0 | Y22: =工作表1!Y22 -> 南門里 | AD22: =工作表1!AD22 -> 東門里 | AM22: =工作表1!M62 -> 0 | AR22: =工作表1!AW52 -> 0 | AS22: =工作表1!AS22 -> 新湖里 | BB22: =工作表1!AW42 -> 0 | BC22: =工作表1!BC22 -> 蓮庵里
L23: =工作表1!BI58 -> 3 | AM23: =工作表1!M63 -> 3 | AR23: =工作表1!AW53 -> 4 | BB23: =工作表1!AW43 -> 3
G24: =工作表1!BI42 -> 0 | L24: =工作表1!BI59 -> 0 | AC24: =工作表1!Y52 -> 0 | AH24: =工作表1!Y42 -> 0 | AM24: =工作表1!M64 -> 0 | AR24: =工作表1!AW54 -> 0 | AW24: =工作表1!AW67 -> 0 | BB24: =工作表1!AW44 -> 0 | BG24: =工作表1!AW73 -> 0
G25: =工作表1!BI43 -> 3 | AC25: =工作表1!Y53 -> 3 | AH25: =工作表1!Y43 -> 4 | AW25: =工作表1!AW68 -> 4 | AX25: =工作表1!AX25 -> 料羅里 | BG25: =工作表1!AW74 -> 5
G26: =工作表1!BI44 -> 0 | AC26: =工作表1!Y54 -> 0 | AH26: =工作表1!Y44 -> 0 | AW26: =工作表1!AW69 -> 0 | BG26: =工作表1!AW75 -> 0
R27: =工作表1!R27 -> 金水里 | W27: =工作表1!W27 -> 賢庵里 | AB27: =工作表1!AB27 -> 珠沙里 | BB27: =工作表1!AW57 -> 0
BB28: =工作表1!AW58 -> 2
V29: =工作表1!Y67 -> 0 | AA29: =工作表1!Y77 -> 0 | AF29: =工作表1!Y72 -> 0 | BB29: =工作表1!AW59 -> 0
V30: =工作表1!Y68 -> 4 | AA30: =工作表1!Y78 -> 3 | AF30: =工作表1!Y73 -> 3
V31: =工作表1!Y69 -> 0 | AA31: =工作表1!Y79 -> 0 | AF31: =工作表1!Y74 -> 0
W32: =工作表1!W32 -> 古城里 | AW32: 大坵村 | BC32: 小坵村
AA34: =工作表1!Y62 -> 0 | BA34: =工作表1!BI69 -> 0 | BG34: =工作表1!BI72 -> 0
AA35: =工作表1!Y63 -> 5 | BA35: =工作表1!BI70 -> 5 | BG35: =工作表1!BI73 -> 2
AA36: =工作表1!Y64 -> 0 | BA36: =工作表1!BI71 -> 0 | BG36: =工作表1!BI74 -> 0

Sheet 金城鎮
A1: 地區 | B1: 姓名 | C1: 號次 | D1: 得票數 | E1: 得票率
A2: 東門里 | B2: ①吳炎成 | C2: 1 | D2: 16 | E2: =D2/SUM(D2:D6) -> 0.016736402
B3: ②李炷烽 | C3: 2 | D3: 423 | E3: =D3/SUM(D2:D6) -> 0.44246862
B4: ③黃積軍 | C4: 3 | D4: 12 | E4: =D4/SUM(D2:D6) -> 0.012552301
B5: ④楊肅元 | C5: 4 | D5: 390 | E5: =D5/SUM(D2:D6) -> 0.40794979
B6: ⑤翟美玉 | C6: 5 | D6: 115 | E6: =D6/SUM(D2:D6) -> 0.12029289
A7: 西門里 | B7: ①吳炎成 | C7: 1 | D7: 24 | E7: =D7/SUM(D7:D11) -> 0.014226437
B8: ②李炷烽 | C8: 2 | D8: 895 | E8: =D8/SUM(D7:D11) -> 0.53052756
B9: ③黃積軍 | C9: 3 | D9: 19 | E9: =D9/SUM(D7:D11) -> 0.011262596
B10: ④楊肅元 | C10: 4 | D10: 351 | E10: =D10/SUM(D7:D11) -> 0.20806165
B11: ⑤翟美玉 | C11: 5 | D11: 398 | E11: =D11/SUM(D7:D11) -> 0.23592175
A12: 南門里 | B12: ①吳炎成 | C12: 1 | D12: 24 | E12: =D12/SUM(D12:D16) -> 0.019093079
B13: ②李炷烽 | C13: 2 | D13: 695 | E13: =D13/SUM(D12:D16) -> 0.55290374
B14: ③黃積軍 | C14: 3 | D14: 24 | E14: =D14/SUM(D12:D16) -> 0.019093079
B15: ④楊肅元 | C15: 4 | D15: 319 | E15: =D15/SUM(D12:D16) -> 0.25377884
B16: ⑤翟美玉 | C16: 5 | D16: 195 | E16: =D16/SUM(D12:D16) -> 0.15513126
A17: 北門里 | B17: ①吳炎成 | C17: 1 | D17: 12 | E17: =D17/SUM(D17:D21) -> 0.014302741
B18: ②李炷烽 | C18: 2 | D18: 463 | E18: =D18/SUM(D17:D21) -> 0.55184744
B19: ③黃積軍 | C19: 3 | D19: 15 | E19: =D19/SUM(D17:D21) -> 0.017878427
B20: ④楊肅元 | C20: 4 | D20: 173 | E20: =D20/SUM(D17:D21) -> 0.20619785
B21: ⑤翟美玉 | C21: 5 | D21: 176 | E21: =D21/SUM(D17:D21) -> 0.20977354
A22: 古城里 | B22: ①吳炎成 | C22: 1 | D22: 10 | E22: =D22/SUM(D22:D26) -> 0.014858841
B23: ②李炷烽 | C23: 2 | D23: 251 | E23: =D23/SUM(D22:D26) -> 0.37295691
B24: ③黃積軍 | C24: 3 | D24: 6 | E24: =D24/SUM(D22:D26) -> 0.0089153046
B25: ④楊肅元 | C25: 4 | D25: 227 | E25: =D25/SUM(D22:D26) -> 0.33729569
B26: ⑤翟美玉 | C26: 5 | D26: 179 | E26: =D26/SUM(D22:D26) -> 0.26597325
A27: 金水里 | B27: ①吳炎成 | C27: 1 | D27: 3 | E27: =D27/SUM(D27:D31) -> 0.0078534031
B28: ②李炷烽 | C28: 2 | D28: 166 | E28: =D28/SUM(D27:D31) -> 0.43455497
B29: ③黃積軍 | C29: 3 | D29: 33 | E29: =D29/SUM(D27:D31) -> 0.086387435
B30: ④楊肅元 | C30: 4 | D30: 88 | E30: =D30/SUM(D27:D31) -> 0.23036649
B31: ⑤翟美玉 | C31: 5 | D31: 92 | E31: =D31/SUM(D27:D31) -> 0.2408377
A32: 珠沙里 | B32: ①吳炎成 | C32: 1 | D32: 3 | E32: =D32/SUM(D32:D36) -> 0.0096774194
B33: ②李炷烽 | C33: 2 | D33: 156 | E33: =D33/SUM(D32:D36) -> 0.50322581
B34: ③黃積軍 | C34: 3 | D34: 2 | E34: =D34/SUM(D32:D36) -> 0.0064516129
B35: ④楊肅元 | C35: 4 | D35: 76 | E35: =D35/SUM(D32:D36) -> 0.24516129
B36: ⑤翟美玉 | C36: 5 | D36: 73 | E36: =D36/SUM(D32:D36) -> 0.23548387
A37: 賢庵里 | B37: ①吳炎成 | C37: 1 | D37: 20 | E37: =D37/SUM(D37:D41) -> 0.034782609
B38: ②李炷烽 | C38: 2 | D38: 337 | E38: =D38/SUM(D37:D41) -> 0.58608696
B39: ③黃積軍 | C39: 3 | D39: 12 | E39: =D39/SUM(D37:D41) -> 0.020869565
B40: ④楊肅元 | C40: 4 | D40: 86 | E40: =D40/SUM(D37:D41) -> 0.14956522
...

Sheet 金寧鄉
A1: 地區 | B1: 姓名 | C1: 號次 | D1: 得票數 | E1: 得票率
A2: 古寧村 | B2: ①吳炎成 | C2: 1 | D2: 5 | E2: =D2/SUM(D2:D6) -> 0.0080906149
B3: ②李炷烽 | C3: 2 | D3: 485 | E3: =D3/SUM(D2:D6) -> 0.78478964
B4: ③黃積軍 | C4: 3 | D4: 5 | E4: =D4/SUM(D2:D6) -> 0.0080906149
B5: ④楊肅元 | C5: 4 | D5: 63 | E5: =D5/SUM(D2:D6) -> 0.10194175
B6: ⑤翟美玉 | C6: 5 | D6: 60 | E6: =D6/SUM(D2:D6) -> 0.097087379
A7: 安美村 | B7: ①吳炎成 | C7: 1 | D7: 14 | E7: =D7/SUM(D7:D11) -> 0.017834395
B8: ②李炷烽 | C8: 2 | D8: 321 | E8: =D8/SUM(D7:D11) -> 0.4089172
B9: ③黃積軍 | C9: 3 | D9: 8 | E9: =D9/SUM(D7:D11) -> 0.010191083
B10: ④楊肅元 | C10: 4 | D10: 302 | E10: =D10/SUM(D7:D11) -> 0.38471338
B11: ⑤翟美玉 | C11: 5 | D11: 140 | E11: =D11/SUM(D7:D11) -> 0.17834395
A12: 后盤村 | B12: ①吳炎成 | C12: 1 | D12: 8 | E12: =D12/SUM(D12:D16) -> 0.031746032
B13: ②李炷烽 | C13: 2 | D13: 165 | E13: =D13/SUM(D12:D16) -> 0.6547619
B14: ③黃積軍 | C14: 3 | D14: 0 | E14: =D14/SUM(D12:D16) -> 0
B15: ④楊肅元 | C15: 4 | D15: 28 | E15: =D15/SUM(D12:D16) -> 0.11111111
B16: ⑤翟美玉 | C16: 5 | D16: 51 | E16: =D16/SUM(D12:D16) -> 0.20238095
A17: 湖埔村 | B17: ①吳炎成 | C17: 1 | D17: 8 | E17: =D17/SUM(D17:D21) -> 0.013157895
B18: ②李炷烽 | C18: 2 | D18: 168 | E18: =D18/SUM(D17:D21) -> 0.27631579
B19: ③黃積軍 | C19: 3 | D19: 2 | E19: =D19/SUM(D17:D21) -> 0.0032894737
B20: ④楊肅元 | C20: 4 | D20: 322 | E20: =D20/SUM(D17:D21) -> 0.52960526
B21: ⑤翟美玉 | C21: 5 | D21: 108 | E21: =D21/SUM(D17:D21) -> 0.17763158
A22: 榜林村 | B22: ①吳炎成 | C22: 1 | D22: 11 | E22: =D22/SUM(D22:D26) -> 0.015714286
B23: ②李炷烽 | C23: 2 | D23: 370 | E23: =D23/SUM(D22:D26) -> 0.52857143
B24: ③黃積軍 | C24: 3 | D24: 5 | E24: =D24/SUM(D22:D26) -> 0.0071428571
B25: ④楊肅元 | C25: 4 | D25: 138 | E25: =D25/SUM(D22:D26) -> 0.19714286
B26: ⑤翟美玉 | C26: 5 | D26: 176 | E26: =D26/SUM(D22:D26) -> 0.25142857
A27: 盤山村 | B27: ①吳炎成 | C27: 1 | D27: 8 | E27: =D27/SUM(D27:D31) -> 0.013816926
B28: ②李炷烽 | C28: 2 | D28: 313 | E28: =D28/SUM(D27:D31) -> 0.54058722
B29: ③黃積軍 | C29: 3 | D29: 1 | E29: =D29/SUM(D27:D31) -> 0.0017271157
B30: ④楊肅元 | C30: 4 | D30: 113 | E30: =D30/SUM(D27:D31) -> 0.19516408
B31: ⑤翟美玉 | C31: 5 | D31: 144 | E31: =D31/SUM(D27:D31) -> 0.24870466

Sheet 金沙鎮
A1: 地區 | B1: 姓名 | C1: 號次 | D1: 得票數 | E1: 得票率
A2: 汶沙里 | B2: ①吳炎成 | C2: 1 | D2: 30 | E2: =D2/SUM(D2:D6) -> 0.029211295
B3: ②李炷烽 | C3: 2 | D3: 558 | E3: =D3/SUM(D2:D6) -> 0.54333009
B4: ③黃積軍 | C4: 3 | D4: 17 | E4: =D4/SUM(D2:D6) -> 0.016553067
B5: ④楊肅元 | C5: 4 | D5: 271 | E5: =D5/SUM(D2:D6) -> 0.26387537
B6: ⑤翟美玉 | C6: 5 | D6: 151 | E6: =D6/SUM(D2:D6) -> 0.14703019
A7: 三山里 | B7: ①吳炎成 | C7: 1 | D7: 11 | E7: =D7/SUM(D7:D11) -> 0.030985915
B8: ②李炷烽 | C8: 2 | D8: 216 | E8: =D8/SUM(D7:D11) -> 0.6084507
B9: ③黃積軍 | C9: 3 | D9: 6 | E9: =D9/SUM(D7:D11) -> 0.016901408
B10: ④楊肅元 | C10: 4 | D10: 40 | E10: =D10/SUM(D7:D11) -> 0.11267606
B11: ⑤翟美玉 | C11: 5 | D11: 82 | E11: =D11/SUM(D7:D11) -> 0.23098592
A12: 大洋里 | B12: ①吳炎成 | C12: 1 | D12: 12 | E12: =D12/SUM(D12:D16) -> 0.05106383
B13: ②李炷烽 | C13: 2 | D13: 120 | E13: =D13/SUM(D12:D16) -> 0.5106383
B14: ③黃積軍 | C14: 3 | D14: 2 | E14: =D14/SUM(D12:D16) -> 0.0085106383
B15: ④楊肅元 | C15: 4 | D15: 26 | E15: =D15/SUM(D12:D16) -> 0.1106383
B16: ⑤翟美玉 | C16: 5 | D16: 75 | E16: =D16/SUM(D12:D16) -> 0.31914894
A17: 光前里 | B17: ①吳炎成 | C17: 1 | D17: 8 | E17: =D17/SUM(D17:D21) -> 0.020618557
B18: ②李炷烽 | C18: 2 | D18: 199 | E18: =D18/SUM(D17:D21) -> 0.5128866
B19: ③黃積軍 | C19: 3 | D19: 13 | E19: =D19/SUM(D17:D21) -> 0.033505155
B20: ④楊肅元 | C20: 4 | D20: 43 | E20: =D20/SUM(D17:D21) -> 0.11082474
B21: ⑤翟美玉 | C21: 5 | D21: 125 | E21: =D21/SUM(D17:D21) -> 0.32216495
A22: 何斗里 | B22: ①吳炎成 | C22: 1 | D22: 14 | E22: =D22/SUM(D22:D26) -> 0.03255814
B23: ②李炷烽 | C23: 2 | D23: 166 | E23: =D23/SUM(D22:D26) -> 0.38604651
B24: ③黃積軍 | C24: 3 | D24: 6 | E24: =D24/SUM(D22:D26) -> 0.013953488
B25: ④楊肅元 | C25: 4 | D25: 70 | E25: =D25/SUM(D22:D26) -> 0.1627907
B26: ⑤翟美玉 | C26: 5 | D26: 174 | E26: =D26/SUM(D22:D26) -> 0.40465116
A27: 西園里 | B27: ①吳炎成 | C27: 1 | D27: 8 | E27: =D27/SUM(D27:D31) -> 0.027777778
B28: ②李炷烽 | C28: 2 | D28: 136 | E28: =D28/SUM(D27:D31) -> 0.47222222
B29: ③黃積軍 | C29: 3 | D29: 9 | E29: =D29/SUM(D27:D31) -> 0.03125
B30: ④楊肅元 | C30: 4 | D30: 53 | E30: =D30/SUM(D27:D31) -> 0.18402778
B31: ⑤翟美玉 | C31: 5 | D31: 82 | E31: =D31/SUM(D27:D31) -> 0.28472222
A32: 官嶼里 | B32: ①吳炎成 | C32: 1 | D32: 1 | E32: =D32/SUM(D32:D36) -> 0.0030120482
B33: ②李炷烽 | C33: 2 | D33: 73 | E33: =D33/SUM(D32:D36) -> 0.21987952
B34: ③黃積軍 | C34: 3 | D34: 2 | E34: =D34/SUM(D32:D36) -> 0.0060240964
B35: ④楊肅元 | C35: 4 | D35: 196 | E35: =D35/SUM(D32:D36) -> 0.59036145
B36: ⑤翟美玉 | C36: 5 | D36: 60 | E36: =D36/SUM(D32:D36) -> 0.18072289
A37: 浦山里 | B37: ①吳炎成 | C37: 1 | D37: 9 | E37: =D37/SUM(D37:D41) -> 0.020501139
B38: ②李炷烽 | C38: 2 | D38: 243 | E38: =D38/SUM(D37:D41) -> 0.55353075
B39: ③黃積軍 | C39: 3 | D39: 5 | E39: =D39/SUM(D37:D41) -> 0.011389522
B40: ④楊肅元 | C40: 4 | D40: 89 | E40: =D40/SUM(D37:D41) -> 0.20273349
...

Sheet 金湖鎮
A1: 地區 | B1: 姓名 | C1: 號次 | D1: 得票數 | E1: 得票率
A2: 新市里 | B2: ①吳炎成 | C2: 1 | D2: 22 | E2: =D2/SUM(D2:D6) -> 0.021093001
B3: ②李炷烽 | C3: 2 | D3: 595 | E3: =D3/SUM(D2:D6) -> 0.5704698
B4: ③黃積軍 | C4: 3 | D4: 14 | E4: =D4/SUM(D2:D6) -> 0.013422819
B5: ④楊肅元 | C5: 4 | D5: 244 | E5: =D5/SUM(D2:D6) -> 0.23394056
B6: ⑤翟美玉 | C6: 5 | D6: 168 | E6: =D6/SUM(D2:D6) -> 0.16107383
A7: 山外里 | B7: ①吳炎成 | C7: 1 | D7: 24 | E7: =D7/SUM(D7:D11) -> 0.032476319
B8: ②李炷烽 | C8: 2 | D8: 381 | E8: =D8/SUM(D7:D11) -> 0.51556157
B9: ③黃積軍 | C9: 3 | D9: 7 | E9: =D9/SUM(D7:D11) -> 0.0094722598
B10: ④楊肅元 | C10: 4 | D10: 125 | E10: =D10/SUM(D7:D11) -> 0.1691475
B11: ⑤翟美玉 | C11: 5 | D11: 202 | E11: =D11/SUM(D7:D11) -> 0.27334235
A12: 正義里 | B12: ①吳炎成 | C12: 1 | D12: 15 | E12: =D12/SUM(D12:D16) -> 0.029069767
B13: ②李炷烽 | C13: 2 | D13: 237 | E13: =D13/SUM(D12:D16) -> 0.45930233
B14: ③黃積軍 | C14: 3 | D14: 14 | E14: =D14/SUM(D12:D16) -> 0.027131783
B15: ④楊肅元 | C15: 4 | D15: 89 | E15: =D15/SUM(D12:D16) -> 0.17248062
B16: ⑤翟美玉 | C16: 5 | D16: 161 | E16: =D16/SUM(D12:D16) -> 0.3120155
A17: 料羅里 | B17: ①吳炎成 | C17: 1 | D17: 10 | E17: =D17/SUM(D17:D21) -> 0.03164557
B18: ②李炷烽 | C18: 2 | D18: 193 | E18: =D18/SUM(D17:D21) -> 0.61075949
B19: ③黃積軍 | C19: 3 | D19: 6 | E19: =D19/SUM(D17:D21) -> 0.018987342
B20: ④楊肅元 | C20: 4 | D20: 45 | E20: =D20/SUM(D17:D21) -> 0.14240506
B21: ⑤翟美玉 | C21: 5 | D21: 62 | E21: =D21/SUM(D17:D21) -> 0.19620253
A22: 瓊林里 | B22: ①吳炎成 | C22: 1 | D22: 19 | E22: =D22/SUM(D22:D26) -> 0.028963415
B23: ②李炷烽 | C23: 2 | D23: 321 | E23: =D23/SUM(D22:D26) -> 0.48932927
B24: ③黃積軍 | C24: 3 | D24: 8 | E24: =D24/SUM(D22:D26) -> 0.012195122
B25: ④楊肅元 | C25: 4 | D25: 167 | E25: =D25/SUM(D22:D26) -> 0.25457317
B26: ⑤翟美玉 | C26: 5 | D26: 141 | E26: =D26/SUM(D22:D26) -> 0.21493902
A27: 新湖里 | B27: ①吳炎成 | C27: 1 | D27: 25 | E27: =D27/SUM(D27:D31) -> 0.035511364
B28: ②李炷烽 | C28: 2 | D28: 348 | E28: =D28/SUM(D27:D31) -> 0.49431818
B29: ③黃積軍 | C29: 3 | D29: 16 | E29: =D29/SUM(D27:D31) -> 0.022727273
B30: ④楊肅元 | C30: 4 | D30: 104 | E30: =D30/SUM(D27:D31) -> 0.14772727
B31: ⑤翟美玉 | C31: 5 | D31: 211 | E31: =D31/SUM(D27:D31) -> 0.29971591
A32: 溪湖里 | B32: ①吳炎成 | C32: 1 | D32: 15 | E32: =D32/SUM(D32:D36) -> 0.046296296
B33: ②李炷烽 | C33: 2 | D33: 157 | E33: =D33/SUM(D32:D36) -> 0.4845679
B34: ③黃積軍 | C34: 3 | D34: 5 | E34: =D34/SUM(D32:D36) -> 0.015432099
B35: ④楊肅元 | C35: 4 | D35: 62 | E35: =D35/SUM(D32:D36) -> 0.19135802
B36: ⑤翟美玉 | C36: 5 | D36: 85 | E36: =D36/SUM(D32:D36) -> 0.26234568
A37: 蓮庵里 | B37: ①吳炎成 | C37: 1 | D37: 2 | E37: =D37/SUM(D37:D41) -> 0.0064308682
B38: ②李炷烽 | C38: 2 | D38: 121 | E38: =D38/SUM(D37:D41) -> 0.38906752
B39: ③黃積軍 | C39: 3 | D39: 8 | E39: =D39/SUM(D37:D41) -> 0.025723473
B40: ④楊肅元 | C40: 4 | D40: 89 | E40: =D40/SUM(D37:D41) -> 0.28617363
...

Sheet 烈嶼鄉
A1: 地區 | B1: 姓名 | C1: 號次 | D1: 得票數 | E1: 得票率
A2: 上岐村 | B2: ①吳炎成 | C2: 1 | D2: 9 | E2: =D2/SUM(D2:D6) -> 0.018442623
B3: ②李炷烽 | C3: 2 | D3: 291 | E3: =D3/SUM(D2:D6) -> 0.59631148
B4: ③黃積軍 | C4: 3 | D4: 6 | E4: =D4/SUM(D2:D6) -> 0.012295082
B5: ④楊肅元 | C5: 4 | D5: 91 | E5: =D5/SUM(D2:D6) -> 0.18647541
B6: ⑤翟美玉 | C6: 5 | D6: 91 | E6: =D6/SUM(D2:D6) -> 0.18647541
A7: 上林村 | B7: ①吳炎成 | C7: 1 | D7: 1 | E7: =D7/SUM(D7:D11) -> 0.0042918455
B8: ②李炷烽 | C8: 2 | D8: 141 | E8: =D8/SUM(D7:D11) -> 0.60515021
B9: ③黃積軍 | C9: 3 | D9: 2 | E9: =D9/SUM(D7:D11) -> 0.008583691
B10: ④楊肅元 | C10: 4 | D10: 18 | E10: =D10/SUM(D7:D11) -> 0.077253219
B11: ⑤翟美玉 | C11: 5 | D11: 71 | E11: =D11/SUM(D7:D11) -> 0.30472103
A12: 西口村 | B12: ①吳炎成 | C12: 1 | D12: 3 | E12: =D12/SUM(D12:D16) -> 0.0088495575
B13: ②李炷烽 | C13: 2 | D13: 127 | E13: =D13/SUM(D12:D16) -> 0.37463127
B14: ③黃積軍 | C14: 3 | D14: 2 | E14: =D14/SUM(D12:D16) -> 0.005899705
B15: ④楊肅元 | C15: 4 | D15: 34 | E15: =D15/SUM(D12:D16) -> 0.10029499
B16: ⑤翟美玉 | C16: 5 | D16: 173 | E16: =D16/SUM(D12:D16) -> 0.51032448
A17: 林湖村 | B17: ①吳炎成 | C17: 1 | D17: 8 | E17: =D17/SUM(D17:D21) -> 0.012820513
B18: ②李炷烽 | C18: 2 | D18: 344 | E18: =D18/SUM(D17:D21) -> 0.55128205
B19: ③黃積軍 | C19: 3 | D19: 5 | E19: =D19/SUM(D17:D21) -> 0.0080128205
B20: ④楊肅元 | C20: 4 | D20: 96 | E20: =D20/SUM(D17:D21) -> 0.15384615
B21: ⑤翟美玉 | C21: 5 | D21: 171 | E21: =D21/SUM(D17:D21) -> 0.27403846
A22: 黃埔村 | B22: ①吳炎成 | C22: 1 | D22: 6 | E22: =D22/SUM(D22:D26) -> 0.023622047
B23: ②李炷烽 | C23: 2 | D23: 113 | E23: =D23/SUM(D22:D26) -> 0.44488189
B24: ③黃積軍 | C24: 3 | D24: 6 | E24: =D24/SUM(D22:D26) -> 0.023622047
B25: ④楊肅元 | C25: 4 | D25: 38 | E25: =D25/SUM(D22:D26) -> 0.1496063
B26: ⑤翟美玉 | C26: 5 | D26: 91 | E26: =D26/SUM(D22:D26) -> 0.35826772

Sheet 烏坵鄉
A1: 地區 | B1: 姓名 | C1: 號次 | D1: 得票數 | E1: 得票率
A2: 大坵村 | B2: ①吳炎成 | C2: 1 | D2: 0 | E2: =D2/SUM(D2:D6) -> 0
B3: ②李炷烽 | C3: 2 | D3: 1 | E3: =D3/SUM(D2:D6) -> 0.076923077
B4: ③黃積軍 | C4: 3 | D4: 0 | E4: =D4/SUM(D2:D6) -> 0
B5: ④楊肅元 | C5: 4 | D5: 3 | E5: =D5/SUM(D2:D6) -> 0.23076923
B6: ⑤翟美玉 | C6: 5 | D6: 9 | E6: =D6/SUM(D2:D6) -> 0.69230769
